<?xml version="1.0" ?>
<robot name="yumi">
  <link name="world"/>
  
  <joint name="world_joint" type="fixed">
  	<parent link="world"/>
  	<child link="yumi_body"/>
  	<origin xyz="0 0 0" rpy="0 0 0"/>
  </joint>
  
  <joint name="yumi_joint_1_r" type="revolute">
    <parent link="yumi_body"/>
    <child link="yumi_link_1_r"/>
    <origin rpy="-0.9795 -0.5682 -2.3155" xyz="0.05355 -0.07249  0.51492"/>
    <axis xyz="0  0  1"/>
      <limit lower="-2.94088" upper="2.94088" effort="300" velocity="3.142" />
    <dynamics damping="0.5"/>
  </joint>
  <joint name="yumi_joint_2_r" type="revolute">
    <parent link="yumi_link_1_r"/>
    <child link="yumi_link_2_r"/>
    <origin rpy="1.5707  0      0" xyz="2.99600000e-02   3.00000000e-05   9.99800000e-02"/>
    <axis xyz="0  0  1"/>
      <limit lower="-2.50455" upper="0.759218" effort="300" velocity="3.142" />
    <dynamics damping="0.5"/>
  </joint>
  <joint name="yumi_joint_7_r" type="revolute">
    <parent link="yumi_link_2_r"/>
    <child link="yumi_link_3_r"/>
    <origin rpy="-1.5707  0      0" xyz="-3.00100000e-02   1.72850000e-01   6.00000000e-05"/>
    <axis xyz="0  0  1"/>
      <limit lower="-2.94088" upper="2.94088" effort="300" velocity="3.142" />
    <dynamics damping="0.5"/>
  </joint>
  <joint name="yumi_joint_3_r" type="revolute">
    <parent link="yumi_link_3_r"/>
    <child link="yumi_link_4_r"/>
    <origin rpy="1.5707  0      0" xyz="-4.18400000e-02  -1.00000000e-05   7.87600000e-02"/>
    <axis xyz="0  0  1"/>
      <limit lower="-2.15548" upper="1.39626" effort="300" velocity="3.142" />
    <dynamics damping="0.5"/>
  </joint>
  <joint name="yumi_joint_4_r" type="revolute">
    <parent link="yumi_link_4_r"/>
    <child link="yumi_link_5_r"/>
    <origin rpy="-1.5707  0      0" xyz="4.15700000e-02   1.64360000e-01   1.00000000e-05"/>
    <axis xyz="0  0  1"/>
      <limit lower="-5.06145" upper="5.06145" effort="300" velocity="6.981" />
    <dynamics damping="0.5"/>
  </joint>
  <joint name="yumi_joint_5_r" type="revolute">
    <parent link="yumi_link_5_r"/>
    <child link="yumi_link_6_r"/>
    <origin rpy="1.5707  0      0" xyz="-2.63800000e-02   6.00000000e-05   1.00550000e-01"/>
    <axis xyz="0  0  1"/>
      <limit lower="-1.53589" upper="2.40855" effort="300" velocity="6.981" />
    <dynamics damping="0.5"/>
  </joint>
  <joint name="yumi_joint_6_r" type="revolute">
    <parent link="yumi_link_6_r"/>
    <child link="yumi_link_7_r"/>
    <origin rpy="-1.5707  0      0" xyz="2.72000000e-02   2.88100000e-02   3.00000000e-05"/>
    <axis xyz="0  0  1"/>
      <limit lower="-3.9968" upper="3.9968" effort="300" velocity="6.981" />
    <dynamics damping="0.5"/>
  </joint>
  
  <joint name="yumi_joint_1_l" type="revolute">
    <parent link="yumi_body"/>
    <child link="yumi_link_1_l"/>
    <origin rpy="0.9781 -0.5716  2.318" xyz="0.05355  0.07249  0.51492"/>
    <axis xyz="0  0  1"/>
      <limit lower="-2.941" upper="2.941" effort="300" velocity="3.142" />
    <dynamics damping="0.5"/>
  </joint>
  <joint name="yumi_joint_2_l" type="revolute">
    <parent link="yumi_link_1_l"/>
    <child link="yumi_link_2_l"/>
    <origin rpy="1.5707  0      0" xyz="0.02997 -0.00015  0.09998"/>
    <axis xyz="0  0  1"/>
      <limit lower="-2.505" upper="0.759" effort="300" velocity="3.142" />
    <dynamics damping="0.5"/>
  </joint>
  <joint name="yumi_joint_7_l" type="revolute">
    <parent link="yumi_link_2_l"/>
    <child link="yumi_link_3_l"/>
    <origin rpy="-1.5707  0      0" xyz="-2.99800000e-02   1.72850000e-01  -1.40000000e-04"/>
    <axis xyz="0  0  1"/>
      <limit lower="-2.941" upper="2.941" effort="300" velocity="3.142" />
    <dynamics damping="0.5"/>
  </joint>
  <joint name="yumi_joint_3_l" type="revolute">
    <parent link="yumi_link_3_l"/>
    <child link="yumi_link_4_l"/>
    <origin rpy="1.5707  0      0" xyz="-0.04183  0.00018  0.07877"/>
    <axis xyz="0  0  1"/>
      <limit lower="-2.155" upper="1.396" effort="300" velocity="3.142" />
    <dynamics damping="0.5"/>
  </joint>
  <joint name="yumi_joint_4_l" type="revolute">
    <parent link="yumi_link_4_l"/>
    <child link="yumi_link_5_l"/>
    <origin rpy="-1.5707  0      0" xyz="0.0416   0.16435  0.00019"/>
    <axis xyz="0  0  1"/>
      <limit lower="-5.061" upper="5.061" effort="300" velocity="6.981" />
    <dynamics damping="0.5"/>
  </joint>
  <joint name="yumi_joint_5_l" type="revolute">
    <parent link="yumi_link_5_l"/>
    <child link="yumi_link_6_l"/>
    <origin rpy="1.5707  0      0" xyz="-2.63600000e-02   3.00000000e-05   1.00550000e-01"/>
    <axis xyz="0  0  1"/>
      <limit lower="-1.536" upper="2.409" effort="300" velocity="6.981" />
    <dynamics damping="0.5"/>
  </joint>
  <joint name="yumi_joint_6_l" type="revolute">
    <parent link="yumi_link_6_l"/>
    <child link="yumi_link_7_l"/>
    <origin rpy="-1.5707  0      0" xyz="2.72100000e-02   2.88000000e-02   8.00000000e-05"/>
    <axis xyz="0  0  1"/>
      <limit lower="-3.997" upper="3.997" effort="300" velocity="6.981" />
    <dynamics damping="0.5"/>
  </joint>
  
  <!--LINKS-->
  <link name="yumi_body">
    <inertial>
      <mass value="15"/>
      <origin rpy="0  0  0" xyz="0   0   0.1"/>
      <inertia ixx="0.6" ixy="0" ixz="0" iyy="0.5" iyz="0" izz="0.3"/>
    </inertial>
    <collision name="collision">
      <origin rpy="0  0  0" xyz="0   0   0.1"/>
      <geometry>
        <mesh filename="yumi/meshes/coarse/body.stl" scale="1.0 1.0 1.0"/>
      </geometry>
    </collision>
    <visual name="test">
      <origin rpy="0  0  0" xyz="0   0   0.1"/>
      <geometry>
        <mesh filename="yumi/meshes/body.stl" scale="1.0 1.0 1.0"/>
      </geometry>
    </visual>
  </link>
  
  <!--RIGHT ARM-->
  <link name="yumi_link_1_r">
 <gravity>0</gravity>
    <inertial>
      <mass value="1"/>
      <origin rpy="0  0  0" xyz="0  0  0"/>
      <inertia ixx="0.1" ixy="0" ixz="0" iyy="0.1" iyz="0" izz="0.1"/>
    </inertial>
    <collision name="collision">
      <origin rpy="0  0  0" xyz="0  0  0"/>
      <geometry>
        <mesh filename="yumi/meshes/coarse/link_1.stl" scale="1.0 1.0 1.0"/>
      </geometry>
    </collision>
    <visual name="yumi_link1">
      <origin rpy="0  0  0" xyz="0  0  0"/>
      <geometry>
        <mesh filename="yumi/meshes/link_1.stl" scale="1.0 1.0 1.0"/>
      </geometry>
    </visual>
  </link>
  <link name="yumi_link_2_r">
 <gravity>0</gravity>
    <inertial>
      <mass value="1"/>
      <origin rpy="0  0  0" xyz="0  0  0"/>
      <inertia ixx="0.1" ixy="0" ixz="0" iyy="0.1" iyz="0" izz="0.1"/>
    </inertial>
    <collision name="collision">
      <origin rpy="0  0  0" xyz="0  0  0"/>
      <geometry>
        <mesh filename="yumi/meshes/coarse/link_2.stl" scale="1.0 1.0 1.0"/>
      </geometry>
    </collision>
    <visual name="yumi_link2">
      <origin rpy="0  0  0" xyz="0  0  0"/>
      <geometry>
        <mesh filename="yumi/meshes/link_2.stl" scale="1.0 1.0 1.0"/>
      </geometry>
    </visual>
  </link>
  <link name="yumi_link_3_r">
 <gravity>0</gravity>
    <inertial>
      <mass value="1"/>
      <origin rpy="0  0  0" xyz="0  0  0"/>
      <inertia ixx="0.1" ixy="0" ixz="0" iyy="0.1" iyz="0" izz="0.1"/>
    </inertial>
    <collision name="collision">
      <origin rpy="0  0  0" xyz="0  0  0"/>
      <geometry>
        <mesh filename="yumi/meshes/coarse/link_3.stl" scale="1.0 1.0 1.0"/>
      </geometry>
    </collision>
    <visual name="yumi_link3">
      <origin rpy="0  0  0" xyz="0  0  0"/>
      <geometry>
        <mesh filename="yumi/meshes/link_3.stl" scale="1.0 1.0 1.0"/>
      </geometry>
    </visual>
  </link>
  <link name="yumi_link_4_r">
 <gravity>0</gravity>
    <inertial>
      <mass value="1"/>
      <origin rpy="0  0  0" xyz="0  0  0"/>
      <inertia ixx="0.1" ixy="0" ixz="0" iyy="0.1" iyz="0" izz="0.1"/>
    </inertial>
    <collision name="collision">
      <origin rpy="0  0  0" xyz="0  0  0"/>
      <geometry>
        <mesh filename="yumi/meshes/coarse/link_4.stl" scale="1.0 1.0 1.0"/>
      </geometry>
    </collision>
    <visual name="yumi_link4">
      <origin rpy="0  0  0" xyz="0  0  0"/>
      <geometry>
        <mesh filename="yumi/meshes/link_4.stl" scale="1.0 1.0 1.0"/>
      </geometry>
    </visual>
  </link>
  <link name="yumi_link_5_r">
 <gravity>0</gravity>
    <inertial>
      <mass value="1"/>
      <origin rpy="0  0  0" xyz="0  0  0"/>
      <inertia ixx="0.1" ixy="0" ixz="0" iyy="0.1" iyz="0" izz="0.1"/>
    </inertial>
    <collision name="collision">
      <origin rpy="0  0  0" xyz="0  0  0"/>
      <geometry>
        <mesh filename="yumi/meshes/coarse/link_5.stl" scale="1.0 1.0 1.0"/>
      </geometry>
    </collision>
    <visual name="yumi_link5">
      <origin rpy="0  0  0" xyz="0  0  0"/>
      <geometry>
        <mesh filename="yumi/meshes/link_5.stl" scale="1.0 1.0 1.0"/>
      </geometry>
    </visual>
  </link>
  <link name="yumi_link_6_r">
 <gravity>0</gravity>
    <inertial>
      <mass value="1"/>
      <origin rpy="0  0  0" xyz="0  0  0"/>
      <inertia ixx="0.1" ixy="0" ixz="0" iyy="0.1" iyz="0" izz="0.1"/>
    </inertial>
    <collision name="collision">
      <origin rpy="0  0  0" xyz="0  0  0"/>
      <geometry>
        <mesh filename="yumi/meshes/coarse/link_6.stl" scale="1.0 1.0 1.0"/>
      </geometry>
    </collision>
    <visual name="yumi_link5">
      <origin rpy="0  0  0" xyz="0  0  0"/>
      <geometry>
        <mesh filename="yumi/meshes/link_6.stl" scale="1.0 1.0 1.0"/>
      </geometry>
    </visual>
  </link>
  <link name="yumi_link_7_r">
 <gravity>0</gravity>
    <inertial>
      <mass value="1"/>
      <origin rpy="0  0  0" xyz="0  0  0"/>
      <inertia ixx="0.1" ixy="0" ixz="0" iyy="0.1" iyz="0" izz="0.1"/>
    </inertial>
    <collision name="collision">
      <origin rpy="0  0  0" xyz="0  0  0"/>
      <geometry>
        <mesh filename="yumi/meshes/coarse/link_7.stl" scale="1.0 1.0 1.0"/>
      </geometry>
    </collision>
    <visual name="yumi_link7">
      <origin rpy="0  0  0" xyz="0  0  0"/>
      <geometry>
        <mesh filename="yumi/meshes/link_7.stl" scale="1.0 1.0 1.0"/>
      </geometry>
    </visual>
  </link>
  
  <!--LEFT ARM-->
  <link name="yumi_link_1_l">
 <gravity>0</gravity>
    <inertial>
      <mass value="1"/>
      <origin rpy="0  0  0" xyz="0  0  0"/>
      <inertia ixx="0.1" ixy="0" ixz="0" iyy="0.1" iyz="0" izz="0.1"/>
    </inertial>
    <collision name="collision">
      <origin rpy="0  0  0" xyz="0  0  0"/>
      <geometry>
        <mesh filename="yumi/meshes/coarse/link_1.stl" scale="1.0 1.0 1.0"/>
      </geometry>
    </collision>
    <visual name="yumi_link1l">
      <origin rpy="0  0  0" xyz="0  0  0"/>
      <geometry>
        <mesh filename="yumi/meshes/link_1.stl" scale="1.0 1.0 1.0"/>
      </geometry>
    </visual>
  </link>
  <link name="yumi_link_2_l">
 <gravity>0</gravity>
    <inertial>
      <mass value="1"/>
      <origin rpy="0  0  0" xyz="0  0  0"/>
      <inertia ixx="0.1" ixy="0" ixz="0" iyy="0.1" iyz="0" izz="0.1"/>
    </inertial>
    <collision name="collision">
      <origin rpy="0  0  0" xyz="0  0  0"/>
      <geometry>
        <mesh filename="yumi/meshes/coarse/link_2.stl" scale="1.0 1.0 1.0"/>
      </geometry>
    </collision>
    <visual name="yumi_link2">
      <origin rpy="0  0  0" xyz="0  0  0"/>
      <geometry>
        <mesh filename="yumi/meshes/link_2.stl" scale="1.0 1.0 1.0"/>
      </geometry>
    </visual>
  </link>
  <link name="yumi_link_3_l">
 <gravity>0</gravity>
    <inertial>
      <mass value="1"/>
      <origin rpy="0  0  0" xyz="0  0  0"/>
      <inertia ixx="0.1" ixy="0" ixz="0" iyy="0.1" iyz="0" izz="0.1"/>
    </inertial>
    <collision name="collision">
      <origin rpy="0  0  0" xyz="0  0  0"/>
      <geometry>
        <mesh filename="yumi/meshes/coarse/link_3.stl" scale="1.0 1.0 1.0"/>
      </geometry>
    </collision>
    <visual name="yumi_link3">
      <origin rpy="0  0  0" xyz="0  0  0"/>
      <geometry>
        <mesh filename="yumi/meshes/link_3.stl" scale="1.0 1.0 1.0"/>
      </geometry>
    </visual>
  </link>
  <link name="yumi_link_4_l">
 <gravity>0</gravity>
    <inertial>
      <mass value="1"/>
      <origin rpy="0  0  0" xyz="0  0  0"/>
      <inertia ixx="0.1" ixy="0" ixz="0" iyy="0.1" iyz="0" izz="0.1"/>
    </inertial>
    <collision name="collision">
      <origin rpy="0  0  0" xyz="0  0  0"/>
      <geometry>
        <mesh filename="yumi/meshes/coarse/link_4.stl" scale="1.0 1.0 1.0"/>
      </geometry>
    </collision>
    <visual name="yumi_link4">
      <origin rpy="0  0  0" xyz="0  0  0"/>
      <geometry>
        <mesh filename="yumi/meshes/link_4.stl" scale="1.0 1.0 1.0"/>
      </geometry>
    </visual>
  </link>
  <link name="yumi_link_5_l">
 <gravity>0</gravity>
    <inertial>
      <mass value="1"/>
      <origin rpy="0  0  0" xyz="0  0  0"/>
      <inertia ixx="0.1" ixy="0" ixz="0" iyy="0.1" iyz="0" izz="0.1"/>
    </inertial>
    <collision name="collision">
      <origin rpy="0  0  0" xyz="0  0  0"/>
      <geometry>
        <mesh filename="yumi/meshes/coarse/link_5.stl" scale="1.0 1.0 1.0"/>
      </geometry>
    </collision>
    <visual name="yumi_link5">
      <origin rpy="0  0  0" xyz="0  0  0"/>
      <geometry>
        <mesh filename="yumi/meshes/link_5.stl" scale="1.0 1.0 1.0"/>
      </geometry>
    </visual>
  </link>
  <link name="yumi_link_6_l">
 <gravity>0</gravity>
    <inertial>
      <mass value="1"/>
      <origin rpy="0  0  0" xyz="0  0  0"/>
      <inertia ixx="0.1" ixy="0" ixz="0" iyy="0.1" iyz="0" izz="0.1"/>
    </inertial>
    <collision name="collision">
      <origin rpy="0  0  0" xyz="0  0  0"/>
      <geometry>
        <mesh filename="yumi/meshes/coarse/link_6.stl" scale="1.0 1.0 1.0"/>
      </geometry>
    </collision>
    <visual name="yumi_link5">
      <origin rpy="0  0  0" xyz="0  0  0"/>
      <geometry>
        <mesh filename="yumi/meshes/link_6.stl" scale="1.0 1.0 1.0"/>
      </geometry>
    </visual>
  </link>
  <link name="yumi_link_7_l">
 <gravity>0</gravity>
    <inertial>
      <mass value="1"/>
      <origin rpy="0  0  0" xyz="0  0  0"/>
      <inertia ixx="0.1" ixy="0" ixz="0" iyy="0.1" iyz="0" izz="0.1"/>
    </inertial>
    <collision name="collision">
      <origin rpy="0  0  0" xyz="0  0  0"/>
      <geometry>
        <mesh filename="yumi/meshes/coarse/link_7.stl" scale="1.0 1.0 1.0"/>
      </geometry>
    </collision>
    <visual name="yumi_link7">
      <origin rpy="0  0  0" xyz="0  0  0"/>
      <geometry>
        <mesh filename="yumi/meshes/link_7.stl" scale="1.0 1.0 1.0"/>
      </geometry>
    </visual>
  </link>
  
  <!--LEFT GRIPPER BASE-->
  <joint name="yumi_joint_8_l" type="fixed">
    <parent link="yumi_link_7_l"/>
    <child link="gripper_l_base"/>
    <origin rpy="0  0  3.1416" xyz="0 0 0.007"/>
  </joint>
  
  <link name="gripper_l_base">
 <gravity>0</gravity>
    <inertial>
      <origin xyz="0 0 0" rpy="0 0 0"/>
      <mass value="0.2"/>
      <inertia ixx="0.0001" ixy="0" ixz="0" iyy="0.0001" iyz="0" izz="0.0001"/>
    </inertial>
    <visual>
      <origin xyz="0 0 0" rpy="0 0 0"/>
      <geometry>
        <mesh filename="yumi/meshes/gripper/base.stl"/>
      </geometry>
    </visual>
    <collision>
      <origin xyz="0 0 0" rpy="0 0 0"/>
      <geometry>
        <mesh filename="yumi/meshes/gripper/coarse/base.stl"/>
      </geometry>
    </collision>
  </link>
  
  <!--LEFT GRIPPER FINGERS-->
  <joint name="yumi_joint_gripper_l_finger_r" type="prismatic">
    <parent link="gripper_l_base"/>
    <child link="gripper_l_finger_r"/>
    <origin xyz="0 -0.0065 0.0837" rpy="0 0 0"/>
    <axis xyz="-1 0 0"/>
      <limit lower="0" upper="0.025" effort="300" velocity="0.02" />
    <dynamics damping="0.5"/>
  </joint>
  
  <link name="gripper_l_finger_r">
 <gravity>0</gravity>
    <inertial>
      <origin xyz="0 0 0" rpy="0 0 0"/>
      <mass value="0.01"/>
      <inertia ixx="0.000001" ixy="0" ixz="0" iyy="0.000001" iyz="0" izz="0.000001"/>
    </inertial>
    <visual>
      <origin xyz="0 0 0" rpy="0 0 0"/>
      <geometry>
        <mesh filename="yumi/meshes/gripper/finger.stl"/>
      </geometry>
    </visual>
    <collision>
      <origin xyz="0 0 0" rpy="0 0 0"/>
      <geometry>
        <mesh filename="yumi/meshes/gripper/coarse/finger.stl"/>
      </geometry>
    </collision>
  </link>
  
  <joint name="yumi_joint_gripper_l_finger_l" type="prismatic">
    <parent link="gripper_l_base"/>
    <child link="gripper_l_finger_l"/>
    <origin xyz="0 0.0065 0.0837" rpy="0 0 3.1416"/>
    <axis xyz="-1 0 0"/>
      <limit lower="0" upper="0.025" effort="300" velocity="0.02" />
    <dynamics damping="0.5"/>
    <mimic joint="yumi_joint_gripper_l_finger_r"/>
  </joint>
  
  <link name="gripper_l_finger_l">
 <gravity>0</gravity>
    <inertial>
      <origin xyz="0 0 0" rpy="0 0 0"/>
      <mass value="0.01"/>
      <inertia ixx="0.000001" ixy="0" ixz="0" iyy="0.000001" iyz="0" izz="0.000001"/>
    </inertial>
    <visual>
      <origin xyz="0 0 0" rpy="0 0 0"/>
      <geometry>
        <mesh filename="yumi/meshes/gripper/finger.stl"/>
      </geometry>
    </visual>
    <collision>
      <origin xyz="0 0 0" rpy="0 0 0"/>
      <geometry>
        <mesh filename="yumi/meshes/gripper/coarse/finger.stl"/>
      </geometry>
    </collision>
  </link>
  
  
  <!--RIGHT GRIPPER BASE-->
  <joint name="yumi_joint_8_r" type="fixed">
    <parent link="yumi_link_7_r"/>
    <child link="gripper_r_base"/>
    <origin rpy="0  0  3.1416" xyz="0 0 0.007"/>
  </joint>
  
  <link name="gripper_r_base">
 <gravity>0</gravity>
    <inertial>
      <origin xyz="0 0 0" rpy="0 0 0"/>
      <mass value="0.2"/>
      <inertia ixx="0.0001" ixy="0" ixz="0" iyy="0.0001" iyz="0" izz="0.0001"/>
    </inertial>
    <visual>
      <origin xyz="0 0 0" rpy="0 0 0"/>
      <geometry>
        <mesh filename="yumi/meshes/gripper/base.stl"/>
      </geometry>
    </visual>
    <collision>
      <origin xyz="0 0 0" rpy="0 0 0"/>
      <geometry>
        <mesh filename="yumi/meshes/gripper/coarse/base.stl"/>
      </geometry>
    </collision>
  </link>
  
  <!--LEFT GRIPPER FINGERS-->
  <joint name="yumi_joint_gripper_r_finger_r" type="prismatic">
    <parent link="gripper_r_base"/>
    <child link="gripper_r_finger_r"/>
    <origin xyz="0 -0.0065 0.0837" rpy="0 0 0"/>
    <axis xyz="-1 0 0"/>
      <limit lower="0" upper="0.025" effort="300" velocity="0.02" />
    <dynamics damping="0.5"/>
  </joint>
  
  <link name="gripper_r_finger_r">
 <gravity>0</gravity>
    <inertial>
      <origin xyz="0 0 0" rpy="0 0 0"/>
      <mass value="0.01"/>
      <inertia ixx="0.000001" ixy="0" ixz="0" iyy="0.000001" iyz="0" izz="0.000001"/>
    </inertial>
    <visual>
      <origin xyz="0 0 0" rpy="0 0 0"/>
      <geometry>
        <mesh filename="yumi/meshes/gripper/finger.stl"/>
      </geometry>
    </visual>
    <collision>
      <origin xyz="0 0 0" rpy="0 0 0"/>
      <geometry>
        <mesh filename="yumi/meshes/gripper/coarse/finger.stl"/>
      </geometry>
    </collision>
  </link>
  
  <joint name="yumi_joint_gripper_r_finger_l" type="prismatic">
    <parent link="gripper_r_base"/>
    <child link="gripper_r_finger_l"/>
    <origin xyz="0 0.0065 0.0837" rpy="0 0 3.1416"/>
    <axis xyz="-1 0 0"/>
      <limit lower="0" upper="0.025" effort="300" velocity="0.02" />
    <dynamics damping="0.5"/>
    <mimic joint="yumi_joint_gripper_r_finger_r"/>
  </joint>
  
  <link name="gripper_r_finger_l">
 <gravity>0</gravity>
    <inertial>
      <origin xyz="0 0 0" rpy="0 0 0"/>
      <mass value="0.01"/>
      <inertia ixx="0.000001" ixy="0" ixz="0" iyy="0.000001" iyz="0" izz="0.000001"/>
    </inertial>
    <visual>
      <origin xyz="0 0 0" rpy="0 0 0"/>
      <geometry>
        <mesh filename="yumi/meshes/gripper/finger.stl"/>
      </geometry>
    </visual>
    <collision>
      <origin xyz="0 0 0" rpy="0 0 0"/>
      <geometry>
        <mesh filename="yumi/meshes/gripper/coarse/finger.stl"/>
      </geometry>
    </collision>
  </link>
  
  
  
  
  
  <!--TRANSMISSIONS FOR ARM LINKS-->
  <transmission name="tran_1_r">
      <type>transmission_interface/SimpleTransmission</type>
      <joint name="yumi_joint_1_r">
	<hardwareInterface>EffortJointInterface</hardwareInterface>
      </joint>
      <actuator name="motor_1_r">
	<mechanicalReduction>1</mechanicalReduction>
	<hardwareInterface>EffortJointInterface</hardwareInterface>
      </actuator>
    </transmission>
    
    <transmission name="tran_2_r">
      <type>transmission_interface/SimpleTransmission</type>
      <joint name="yumi_joint_2_r">
	<hardwareInterface>EffortJointInterface</hardwareInterface>
      </joint>
      <actuator name="motor_2_r">
	<mechanicalReduction>1</mechanicalReduction>
	<hardwareInterface>EffortJointInterface</hardwareInterface>
      </actuator>
    </transmission>
    
    <transmission name="tran_7_r">
      <type>transmission_interface/SimpleTransmission</type>
      <joint name="yumi_joint_7_r">
	<hardwareInterface>EffortJointInterface</hardwareInterface>
      </joint>
      <actuator name="motor_7_r">
	<mechanicalReduction>1</mechanicalReduction>
	<hardwareInterface>EffortJointInterface</hardwareInterface>
      </actuator>
    </transmission>
    
    <transmission name="tran_3_r">
      <type>transmission_interface/SimpleTransmission</type>
      <joint name="yumi_joint_3_r">
	<hardwareInterface>EffortJointInterface</hardwareInterface>
      </joint>
      <actuator name="motor_3_r">
	<mechanicalReduction>1</mechanicalReduction>
	<hardwareInterface>EffortJointInterface</hardwareInterface>
      </actuator>
    </transmission>
    
    <transmission name="tran_4_r">
      <type>transmission_interface/SimpleTransmission</type>
      <joint name="yumi_joint_4_r">
	<hardwareInterface>EffortJointInterface</hardwareInterface>
      </joint>
      <actuator name="motor_4_r">
	<mechanicalReduction>1</mechanicalReduction>
	<hardwareInterface>EffortJointInterface</hardwareInterface>
      </actuator>
    </transmission>
    
    <transmission name="tran_5_r">
      <type>transmission_interface/SimpleTransmission</type>
      <joint name="yumi_joint_5_r">
	<hardwareInterface>EffortJointInterface</hardwareInterface>
      </joint>
      <actuator name="motor_5_r">
	<mechanicalReduction>1</mechanicalReduction>
	<hardwareInterface>EffortJointInterface</hardwareInterface>
      </actuator>
    </transmission>
    
    <transmission name="tran_6_r">
      <type>transmission_interface/SimpleTransmission</type>
      <joint name="yumi_joint_6_r">
	<hardwareInterface>EffortJointInterface</hardwareInterface>
      </joint>
      <actuator name="motor_6_r">
	<mechanicalReduction>1</mechanicalReduction>
	<hardwareInterface>EffortJointInterface</hardwareInterface>
      </actuator>
    </transmission>
    
    <transmission name="tran_1_l">
      <type>transmission_interface/SimpleTransmission</type>
      <joint name="yumi_joint_1_l">
	<hardwareInterface>EffortJointInterface</hardwareInterface>
      </joint>
      <actuator name="motor_1_l">
	<mechanicalReduction>1</mechanicalReduction>
	<hardwareInterface>EffortJointInterface</hardwareInterface>
      </actuator>
    </transmission>
    
    <transmission name="tran_2_l">
      <type>transmission_interface/SimpleTransmission</type>
      <joint name="yumi_joint_2_l">
	<hardwareInterface>EffortJointInterface</hardwareInterface>
      </joint>
      <actuator name="motor_2_l">
	<mechanicalReduction>1</mechanicalReduction>
	<hardwareInterface>EffortJointInterface</hardwareInterface>
      </actuator>
    </transmission>
    
    <transmission name="tran_7_l">
      <type>transmission_interface/SimpleTransmission</type>
      <joint name="yumi_joint_7_l">
	<hardwareInterface>EffortJointInterface</hardwareInterface>
      </joint>
      <actuator name="motor_7_l">
	<mechanicalReduction>1</mechanicalReduction>
	<hardwareInterface>EffortJointInterface</hardwareInterface>
      </actuator>
    </transmission>
    
    <transmission name="tran_3_l">
      <type>transmission_interface/SimpleTransmission</type>
      <joint name="yumi_joint_3_l">
	<hardwareInterface>EffortJointInterface</hardwareInterface>
      </joint>
      <actuator name="motor_3_l">
	<mechanicalReduction>1</mechanicalReduction>
	<hardwareInterface>EffortJointInterface</hardwareInterface>
      </actuator>
    </transmission>
    
    <transmission name="tran_4_l">
      <type>transmission_interface/SimpleTransmission</type>
      <joint name="yumi_joint_4_l">
	<hardwareInterface>EffortJointInterface</hardwareInterface>
      </joint>
      <actuator name="motor_4_l">
	<mechanicalReduction>1</mechanicalReduction>
	<hardwareInterface>EffortJointInterface</hardwareInterface>
      </actuator>
    </transmission>
    
    <transmission name="tran_5_l">
      <type>transmission_interface/SimpleTransmission</type>
      <joint name="yumi_joint_5_l">
	<hardwareInterface>EffortJointInterface</hardwareInterface>
      </joint>
      <actuator name="motor_5_l">
	<mechanicalReduction>1</mechanicalReduction>
	<hardwareInterface>EffortJointInterface</hardwareInterface>
      </actuator>
    </transmission>
    
    <transmission name="tran_6_l">
      <type>transmission_interface/SimpleTransmission</type>
      <joint name="yumi_joint_6_l">
	<hardwareInterface>EffortJointInterface</hardwareInterface>
      </joint>
      <actuator name="motor_6_l">
	<mechanicalReduction>1</mechanicalReduction>
	<hardwareInterface>EffortJointInterface</hardwareInterface>
      </actuator>
    </transmission>
    
    <transmission name="tran_gripper_l">
      <type>transmission_interface/SimpleTransmission</type>
      <joint name="yumi_joint_gripper_l_finger_r">
	<hardwareInterface>EffortJointInterface</hardwareInterface>
      </joint>
      <actuator name="motor_8_l">
	<mechanicalReduction>1</mechanicalReduction>
	<hardwareInterface>EffortJointInterface</hardwareInterface>
      </actuator>
    </transmission> 

    <transmission name="tran_gripper_ll">
      <type>transmission_interface/SimpleTransmission</type>
      <joint name="yumi_joint_gripper_l_finger_l">
	<hardwareInterface>EffortJointInterface</hardwareInterface>
      </joint>
      <actuator name="motor_8_ll">
	<mechanicalReduction>1</mechanicalReduction>
	<hardwareInterface>EffortJointInterface</hardwareInterface>
      </actuator>
    </transmission>    
    
    <transmission name="tran_gripper_r">
      <type>transmission_interface/SimpleTransmission</type>
      <joint name="yumi_joint_gripper_r_finger_r">
	<hardwareInterface>EffortJointInterface</hardwareInterface>
      </joint>
      <actuator name="motor_8_r">
	<mechanicalReduction>1</mechanicalReduction>
	<hardwareInterface>EffortJointInterface</hardwareInterface>
      </actuator>
    </transmission>  

    <transmission name="tran_gripper_rr">
      <type>transmission_interface/SimpleTransmission</type>
      <joint name="yumi_joint_gripper_r_finger_l">
	<hardwareInterface>EffortJointInterface</hardwareInterface>
      </joint>
      <actuator name="motor_8_rr">
	<mechanicalReduction>1</mechanicalReduction>
	<hardwareInterface>EffortJointInterface</hardwareInterface>
      </actuator>
    </transmission>    
    
     <!-- ros_control plugin -->
  <gazebo>
    <plugin name="gazebo_ros_control" filename="libgazebo_ros_control.so">
      <robotNamespace>/yumi</robotNamespace>
      <robotSimType>gazebo_ros_control/DefaultRobotHWSim</robotSimType>
    </plugin>
  </gazebo>


</robot>
